<?xml version="1.0" ?>
<!-- =================================================================================== -->
<!-- |    This document was autogenerated by xacro from right_arm.urdf.xacro           | -->
<!-- |    EDITING THIS FILE BY HAND IS NOT RECOMMENDED                                 | -->
<!-- =================================================================================== -->
<robot name="right_arm">
<link name="world">
	</link>

	<joint name="world_to_base" type="fixed">
		<origin xyz="0 0 0" rpy="0 0 0" />
		<parent link="world" />
		<child link="base_link" />
	</joint> -->
  <link name="base_link">
    <visual>
      <material name="SoftLightBlue" />
      <geometry>
        <mesh
          filename="package://alterego_robot/alterego_description/meshes/alterego_v3/visual/aego_base.dae"
          scale="0.001 0.001 0.001" />
      </geometry>
      <origin rpy="0 0 0" xyz="0 0 0" />
    </visual>
    <inertial>
      <origin rpy="0 0 0" xyz="-6.0298829e-3 2.5874338e-4 3.3410009e-1" />
      <mass value="2.3743e+1" />
      <inertia ixx=" 3.1258968" ixy="-1.5892316e-3" ixz="-4.7850173e-2" iyy="2.9578724"
        iyz="-5.7425852e-4" izz="2.6379126e-1" />
    </inertial>
    <collision>
      <geometry>
        <mesh
          filename="package://alterego_robot/alterego_description/meshes/alterego_v3/collision/aego_base.stl"
          scale="0.001 0.001 0.001" />
      </geometry>
      <origin rpy="0 0 0" xyz="0 0 0" />
    </collision>
  </link>
  <link name="torso">
	</link>
  <joint name="base_to_torso" type="fixed">
    <origin rpy="0 0 0" xyz="-0.0 0 0.874939" />
    <parent link="base_link" />
    <child link="torso" />
  </joint>
<!-- JOINT -->
  <joint name="base_link_to_right_shoulder_flange" type="revolute">
    <axis xyz="0 0 1" />
    <limit effort="1000.0" lower="-3.14" upper="3.14" velocity="0.5" />
    <origin rpy="0.1745345 -1.3962633 1.5707948" xyz="28.6482e-3 -220.259e-3 901.246e-3" />
    <dynamics damping="0.065" friction="0.025" />
    <parent link="base_link" />
    <child link="right_shoulder_flange" />
  </joint>
  <!-- LINK -->
  <link name="right_shoulder_flange">
    <visual>
      <material name="qbmove/flange" />
      <geometry>
        <mesh
          filename="package://alterego_robot/alterego_description/meshes/common/visual/la_flg_asm_flat_blu.dae"
          scale="0.001 0.001 0.001" />
      </geometry>
      <origin rpy="0 0 0" xyz="0 0 0" />
    </visual>
    <inertial>
      <origin rpy="0 0 0" xyz="-8.0511890e-5 0 6.1371397e-4" />
      <mass value="4.1898263e-02" />
      <inertia ixx="1.5773084e-5" ixy="0" ixz="0" iyy="2.1042697e-5" iyz="0" izz="3.6312308e-5" />
    </inertial>
    <collision>
      <material name="qbmove/cube" />
      <origin rpy="0 0 0" xyz="0 0 0" />
      <geometry>
        <mesh
          filename="package://alterego_robot/alterego_description/meshes/common/collision/la_flg_asm_flat_blu.stl"
          scale="0.001 0.001 0.001" />
      </geometry>
    </collision>
  </link>
  <!-- JOINT -->
  <joint name="right_shoulder_flange_to_right_shoulder_cube" type="fixed">
    <origin rpy="-1.5707963 0 3.1415927" xyz="0 0.5e-3 37e-3" />
    <parent link="right_shoulder_flange" />
    <child link="right_shoulder_cube" />
  </joint>
  <!-- LINK -->
  <link name="right_shoulder_cube">
    <visual>
      <material name="qbmove/cube" />
      <geometry>
        <mesh
          filename="package://alterego_robot/alterego_description/meshes/alterego_v3/visual/qb_mate_advanced_plus_add.dae"
          scale="0.001 0.001 0.001" />
      </geometry>
      <origin rpy="0 0 0" xyz="0 0 0" />
    </visual>
    <inertial>
      <origin rpy="0 0 0" xyz="-6.7920088e-5 -1.0259859e-5  3.3111200e-3" />
      <mass value="6.6127705e-1" />
      <inertia ixx="5.5302425e-4" ixy="-1.7453168e-5" ixz="-1.5101777e-6" iyy="5.5130433e-4" iyz="0"
        izz="2.8634544e-4" />
    </inertial>
    <collision>
      <origin rpy="0.0 0.0 0.0" xyz="0.0 0.0 0.0" />
      <geometry>
        <box size="0.07 0.07 0.07" />
      </geometry>
    </collision>
  </link>
  <!-- JOINT -->
  <joint name="right_shoulder_cube_to_right_arm_flange" type="revolute">
    <axis xyz="0 0 1" />
    <limit effort="1000.0" lower="-3.14" upper="3.14" velocity="0.5" />
    <origin rpy="0 0 3.1415927" xyz="0 0 0.5e-3" />
    <dynamics damping="0.065" friction="0.025" />
    <parent link="right_shoulder_cube" />
    <child link="right_arm_flange" />
  </joint>
  <!-- LINK -->
  <link name="right_arm_flange">
    <visual>
      <material name="qbmove/flange" />
      <geometry>
        <mesh
          filename="package://alterego_robot/alterego_description/meshes/alterego_v3/visual/la_flg_c_wb_large.dae"
          scale="0.001 0.001 0.001" />
      </geometry>
      <origin rpy="0 0 0" xyz="0 0 0" />
    </visual>
    <inertial>
      <origin rpy="0 0 0" xyz="6.4001753e-3 1.4674945e-2 0" />
      <mass value="1.2524265e-01" />
      <inertia ixx="1.1014959e-4" ixy="-3.0957793e-5" ixz="0" iyy="2.3068924e-4" iyz="0"
        izz="2.7657409e-4" />
    </inertial>
    <collision>
      <origin rpy="0 0 0" xyz="0 0 0" />
      <geometry>
        <mesh
          filename="package://alterego_robot/alterego_description/meshes/alterego_v3/collision/la_flg_c_wb_large.stl"
          scale="0.001 0.001 0.001" />
      </geometry>
    </collision>
  </link>
  <!-- JOINT -->
  <joint name="right_arm_flange_to_right_arm_cube" type="fixed">
    <origin rpy="0 1.5707963 3.1415927" xyz="-90e-3 0 0" />
    <parent link="right_arm_flange" />
    <child link="right_arm_cube" />
  </joint>
  <!-- LINK -->
  <link name="right_arm_cube">
    <visual>
      <material name="qbmove/cube" />
      <geometry>
        <mesh
          filename="package://alterego_robot/alterego_description/meshes/common/visual/qb_move_advanced_for_mate.dae"
          scale="0.001 0.001 0.001" />
      </geometry>
      <origin rpy="0 0 0" xyz="0 0 0" />
    </visual>
    <inertial>
      <origin rpy="0 0 0" xyz="-9.5664949e-5 -1.6749134e-5  1.3880927e-3" />
      <mass value="4.5418805e-1" />
      <inertia ixx="1.7978900e-4" ixy="0" ixz="0" iyy="1.7806823e-4" iyz="0" izz="1.6882624e-4" />
    </inertial>
    <collision>
      <origin rpy="0.0 0.0 0.0" xyz="0.0 0.0 0.0" />
      <geometry>
        <box size="0.07 0.07 0.07" />
      </geometry>
    </collision>
  </link>
   <!-- IMU : -->
  <joint name="right_arm_cube_to_right_elbow_flange_sensor" type="revolute">
    <axis xyz="0 0 1" />
    <limit effort="1000.0" lower="-3.14" upper="3.14" velocity="0.5" />
    <dynamics damping="0.065" friction="0.025" />
    <origin rpy="0 0 1.5707963" xyz="0.0 0.0 66.5e-3" />
    <parent link="right_arm_cube" />
    <child link="right_elbow_flange_sensor" />
  </joint>
  <link name="right_elbow_flange_sensor">
    <visual>
      <material name="qbmove/cube" />
      <geometry>
        <mesh
          filename="package://alterego_robot/alterego_description/meshes/alterego_v3/visual/fsens_hinge_001.dae"
          scale="0.001 0.001 0.001" />
      </geometry>
      <origin rpy="0 0 0" xyz="0 0 0" />
    </visual>
    <inertial>
      <origin rpy="0 0 0" xyz="0 -7.3560725e-4 -2.2326727e-3" />
      <mass value="1.0238457e-01" />
      <inertia ixx="5.9037323e-5" ixy="0" ixz="0" iyy="5.3509057e-5" iyz="0" izz="8.7851500e-5" />
    </inertial>
    <collision>
      <origin rpy="0 0 0" xyz="0 0 0" />
      <geometry>
        <mesh
          filename="package://alterego_robot/alterego_description/meshes/alterego_v3/collision/fsens_hinge_001.stl"
          scale="0.001 0.001 0.001" />
      </geometry>
    </collision>
  </link>
  <!-- JOINT -->
  <joint name="right_elbow_flange_sensor_to_right_elbow_flange" type="fixed">
    <axis xyz="0 0 1" />
    <limit effort="1000.0" lower="-3.14" upper="3.14" velocity="0.5" />
    <origin rpy="0 0 -1.5707963" xyz="0 0 18e-3" />
    <dynamics damping="0.065" friction="0.025" />
    <parent link="right_elbow_flange_sensor" />
    <child link="right_elbow_flange" />
  </joint>
  <!-- LINK -->
  <link name="right_elbow_flange">
    <visual>
      <material name="qbmove/flange" />
      <geometry>
        <mesh
          filename="package://alterego_robot/alterego_description/meshes/common/visual/la_flg_asm_flat_blu.dae"
          scale="0.001 0.001 0.001" />
      </geometry>
      <origin rpy="0 0 0" xyz="0 0 0" />
    </visual>
    <inertial>
      <origin rpy="0 0 0" xyz="-8.0511890e-5 0 6.1371397e-4" />
      <mass value="4.1898263e-02" />
      <inertia ixx="1.5773084e-5" ixy="0" ixz="0" iyy="2.1026644e-5" iyz="0" izz="3.6312308e-5" />
    </inertial>
    <collision>
      <origin rpy="0 0 0" xyz="0 0 0" />
      <geometry>
        <mesh
          filename="package://alterego_robot/alterego_description/meshes/common/collision/la_flg_asm_flat_blu.stl"
          scale="0.001 0.001 0.001" />
      </geometry>
    </collision>
  </link>
  <!-- JOINT -->
  <joint name="right_elbow_flange_to_right_elbow_cube" type="fixed">
    <origin rpy="1.5707963 0 0" xyz="0 0 37e-3" />
    <parent link="right_elbow_flange" />
    <child link="right_elbow_cube" />
  </joint>
  <!-- LINK -->
  <link name="right_elbow_cube">
    <visual>
      <material name="qbmove/cube" />
      <geometry>
        <mesh
          filename="package://alterego_robot/alterego_description/meshes/common/visual/qb_move_advanced_for_mate.dae"
          scale="0.001 0.001 0.001" />
      </geometry>
      <origin rpy="0 0 0" xyz="0 0 0" />
    </visual>
    <inertial>
      <origin rpy="0 0 0" xyz="-9.5664949e-5 -1.6749134e-5  1.3880927e-3" />
      <mass value="4.5418805e-1" />
      <inertia ixx="1.7978900e-4" ixy="0" ixz="0" iyy="1.7806823e-4" iyz="0" izz="1.6882624e-4" />
    </inertial>
    <collision>
      <origin rpy="0.0 0.0 0.0" xyz="0.0 0.0 0.0" />
      <geometry>
        <box size="0.07 0.07 0.07" />
      </geometry>
    </collision>
  </link>
  <!-- JOINT -->
  <joint name="right_elbow_cube_to_right_forearm_flange" type="revolute">
    <axis xyz="0 0 1" />
    <limit effort="1000.0" lower="-3.14" upper="3.14" velocity="0.5" />
    <origin rpy="0 0 -1.5707963" xyz="0 0 -0.5e-3" />
    <dynamics damping="0.065" friction="0.025" />
    <parent link="right_elbow_cube" />
    <child link="right_forearm_flange" />
  </joint>
  <!-- LINK -->
  <link name="right_forearm_flange">
    <visual>
      <material name="qbmove/flange" />
      <geometry>
        <mesh
          filename="package://alterego_robot/alterego_description/meshes/common/visual/la_flg_asm_c_wb_blu.dae"
          scale="0.001 0.001 0.001" />
      </geometry>
      <origin rpy="0 0 0" xyz="0 0 0" />
    </visual>
    <inertial>
      <origin rpy="0 0 0" xyz="-7.3157519e-3 2.3015782e-2 0" />
      <mass value="8.6640591e-2" />
      <inertia ixx="7.8695858e-5" ixy="1.8826444e-5" ixz="0" iyy="1.0265668e-4" iyz="0"
        izz="1.3810438e-4" />
    </inertial>
    <collision>
      <origin rpy="0 0 0" xyz="0 0 0" />
      <geometry>
        <mesh
          filename="package://alterego_robot/alterego_description/meshes/common/collision/la_flg_asm_c_wb_blu.stl"
          scale="0.001 0.001 0.001" />
      </geometry>
    </collision>
  </link>
  <!-- JOINT -->
  <joint name="right_forearm_flange_to_right_forearm_cube" type="fixed">
    <origin rpy="-1.5707963 0 1.5707963" xyz="-90e-3 0 0" />
    <parent link="right_forearm_flange" />
    <child link="right_forearm_cube" />
  </joint>
  <!-- LINK -->
  <link name="right_forearm_cube">
    <visual>
      <material name="qbmove/cube" />
      <geometry>
        <mesh
          filename="package://alterego_robot/alterego_description/meshes/common/visual/qb_move_advanced_for_mate.dae"
          scale="0.001 0.001 0.001" />
      </geometry>
      <origin rpy="0 0 0" xyz="0 0 0" />
    </visual>
    <inertial>
      <origin rpy="0 0 0" xyz="-9.5664949e-5 -1.6749134e-5  1.3880927e-3" />
      <mass value="4.5418805e-1" />
      <inertia ixx="1.7978900e-4" ixy="0" ixz="0" iyy="1.7806823e-4" iyz="0" izz="1.6882624e-4" />
    </inertial>
    <collision>
      <origin rpy="0.0 0.0 0.0" xyz="0.0 0.0 0.0" />
      <geometry>
        <box size="0.07 0.07 0.07" />
      </geometry>
    </collision>
  </link>
  <!-- JOINT -->
  <joint name="right_forearm_cube_to_right_wrist_flange" type="revolute">
    <axis xyz="0 0 1" />
    <limit effort="1000.0" lower="-3.14" upper="3.14" velocity="0.5" />
    <origin rpy="0 0 -1.5707963" xyz="0.0 0.0 40.5e-3" />
    <dynamics damping="0.065" friction="0.025" />
    <parent link="right_forearm_cube" />
    <child link="right_wrist_flange" />
  </joint>
  <!-- LINK -->
  <link name="right_wrist_flange">
    <visual>
      <material name="qbmove/flange" />
      <geometry>
        <mesh
          filename="package://alterego_robot/alterego_description/meshes/common/visual/la_flg_asm_flat_blu.dae"
          scale="0.001 0.001 0.001" />
      </geometry>
      <origin rpy="0 0 0" xyz="0 0 0" />
    </visual>
    <inertial>
      <origin rpy="0 0 0" xyz="-8.0511890e-5 0 6.1371397e-4" />
      <mass value="4.1898263e-02" />
      <inertia ixx="1.5773084e-5" ixy="0" ixz="0" iyy="2.1026644e-5" iyz="0" izz="3.6312308e-5" />
    </inertial>
    <collision>
      <origin rpy="0 0 0" xyz="0 0 0" />
      <geometry>
        <mesh
          filename="package://alterego_robot/alterego_description/meshes/common/collision/la_flg_asm_flat_blu.stl"
          scale="0.001 0.001 0.001" />
      </geometry>
    </collision>
  </link>
   <!-- JOINT -->
  <joint name="right_wrist_flange_to_right_wrist" type="fixed">
    <origin rpy="-1.5707963 0 3.1415927" xyz="-11.9e-3 0 99.8636e-3" />
    <parent link="right_wrist_flange" />
    <child link="right_wrist" />
  </joint>
  <!-- LINK -->
  <link name="right_wrist">
    <visual>
      <material name="qbmove/cube" />
      <geometry>
        <mesh
          filename="package://alterego_robot/alterego_description/meshes/alterego_v3/visual/right_wrist_v2_1_urdf.dae"
          scale="0.001 0.001 0.001" />
      </geometry>
      <origin rpy="0 0 0" xyz="0 0 0" />
    </visual>
    <inertial>
      <origin rpy="0 0 0" xyz="-1.0015996e-2 -4.7977946e-2  7.1379217e-3" />
      <mass value="7.1363493e-01" />
      <inertia ixx=" 8.9951899e-4" ixy="-6.4509373e-5" ixz="-9.6528261e-6" iyy=" 4.9791497e-4"
        iyz="-3.7410480e-5" izz="7.0476751e-4" />
    </inertial>
    <collision>
      <material name="qbmove/cube" />
      <geometry>
        <mesh
          filename="package://alterego_robot/alterego_description/meshes/alterego_v3/collision/right_wrist_v2_1_urdf.stl"
          scale="0.001 0.001 0.001" />
      </geometry>
      <origin rpy="0 0 0" xyz="0 0 0" />
    </collision>
  </link>
  <!-- JOINT -->
  <joint name="right_wrist_to_right_hand" type="revolute">
    <axis xyz="0 0 1" />
    <limit effort="1000.0" lower="-1.57" upper="1.57" velocity="0.5" />
    <origin rpy="0 0 0" xyz="0 0 0.0" />
    <parent link="right_wrist" />
    <child link="right_hand" />
  </joint>
  <!-- LINK -->
  <link name="right_hand">
    <visual>
      <material name="qbmove/cube" />
      <geometry>
        <mesh
          filename="package://alterego_robot/alterego_description/meshes/common/visual/softhand_3_dx_urdf.dae"
          scale="0.001 0.001 0.001" />
      </geometry>
      <origin rpy="0 0 0" xyz="0 0 0" />
    </visual>
    <inertial>
      <origin rpy="0 0 0" xyz="4.1739778e-3  -6.3138073e-2 6.1007501e-3" />
      <mass value="2.9013125e-1" />
      <inertia ixx="5.6377846e-4" ixy="-2.5891425e-5" ixz="-1.0142109e-5" iyy="1.4989796e-4"
        iyz="5.9361645e-6" izz="4.4769789e-4" />
    </inertial>
    <collision>
      <material name="qbmove/cube" />
      <geometry>
        <mesh
          filename="package://alterego_robot/alterego_description/meshes/common/collision/softhand_3_dx_urdf.stl"
          scale="0.001 0.001 0.001" />
      </geometry>
      <origin rpy="0 0 0" xyz="0 0 0" />
    </collision>
  </link>
  <joint name="right_hand_to_right_hand__ik" type="fixed">
    <origin rpy="0 0 -1.57" xyz="0 -0.088 0.032" />
    <parent link="right_hand" />
    <child link="right_hand_ik" />
  </joint>
  <link name="right_hand_ik">
</link>
</robot>

		

